Workbook

Sheet Beschreibung
C3: 150 analysierbare Beiträge mit Kaffee wurden aus dem Korpus extrahiert. Nicht analysierbare Beiträge, wie etwa Hyperlinks mit Kaffee, wurden von der Untersuchung ausgeschlossen, wie das Beispiel unten:
C7: WDD17/A11.44456 Diskussion:Arabica-Kaffee, In: Wikipedia - URL:http://de.wikipedia.org/wiki/Diskussion:Arabica-Kaffee: Wikipedia, 2017
C9: Insgesamt wurden 2276 Beiträge mit Kaffee im Korpus von dem Algorithmus analysiert. Die Genuszuweisungen von Kaffee wurden davon wie folgt zugeordnet:
D13: Ergebnis | G13: n | H13: %
D14: Nicht feststellbar | G14: 1228 | H14: =G14/G$17 -> 0.53954306
D15: Maskulinium oder Neutrum | G15: 973 | H15: =G15/G$17 -> 0.42750439
D16: Femininum | G16: 75 | H16: =G16/G$17 -> 0.032952548
D17: Summe | G17: =SUM(G14:G16) -> 2276 | H17: =SUM(H14:H16) -> 1
B22: Siehe „Manuelle Überprüfung von 150" für die durchgeführte Überprüfung, der in der Arbeit beschrieben wird.
B24: Gunnar Brådvik
B25: gunnar@bradvik.se
B26: 3. Februar 2026

Sheet Manuelle Überprüfung von 150
A1: Nummer | B1: Beitrag | C1: Genuszuweisung (manuell) | D1: Genuszuweisung (Algorithmus) | E1: Korrektes Ergebnis vom Algorithmus | F1: Kommentar/Grund des Fehlers
A2: 1 | B2: Hitler war seit seiner Jugendzeit Nichtraucher und trank keinen Alkohol, später auch keinen Kaffee und Schwarztee. Zudem wurde er 1932 aus Furcht vor einer Magenkrebserkrankung gemäßigter Vegetarier. Diese Ernährungsgewohnheiten behielt er als Reichskanzler bei und thematisierte sie in Monologen vor dem engsten Anhängerkreis auch als Mittel für die nationalsozialistische Gesundheitspolitik." " | C2: Maskulinum oder Neutrum | D2: Maskulinum oder Neutrum | E2: =IF(C2="NICHT-ANALYSIERT", "NA", IF(C2=D2, 1, 0)) -> 1 | F2: Negationsartikel (-en), Akkusativ
A3: 2 | B3: Ich glaube bzg. Koffeinsucht sollte man sich mal in Gefängnissen umhören. Da wird z.B. löslicher Kaffee mit Cola aufgemischt um sich anzudröhnen. Dies hat alle Merkmale einer Sucht! Evtl. braucht man ein anderes Wort dafür. Aber auch die Entzugerscheinungen eines ausgibigen, regelmäßigen Kaffee-Trinkers entsprechen den Suchtdefinitionen. | C3: Maskulinum oder Neutrum | D3: Maskulinum oder Neutrum | E3: =IF(C3="NICHT-ANALYSIERT", "NA", IF(C3=D3, 1, 0)) -> 1 | F3: Adjektivflexion, -er
A4: 3 | B4: Da die Volkswirtschaft sehr von den Erlösen aus landwirtschaftlichem Anbau abhängt (Kaffee, Kakao, Palmöl, Holz etc.) sind bei einem weltweitem Überangebot dieser Produkte die Erlöse seit Jahren rückläufig, was sich sicherlich langfristig nicht positv auf die Stabilität, Sicherheit etc. auswirken kann. Verursacher hierfür ist meines Erachten vor Allem der Westen (Europäische Gemeinschaft, Weltbank etc.), die vielen afrikanischen Staaten Kredite aufgedrängt und sie dann in eine Überproduktion der o. g. landwirtschaftlichen Güter geführt haben, was die Abhängigkeit vom Westen dann noch mehr verstärkt hat. So sind die Exportpreise für Kaffee / Kakao seit Jahrzehnten rückläufig... | C4: Nicht feststellbar | D4: Nicht feststellbar | E4: =IF(C4="NICHT-ANALYSIERT", "NA", IF(C4=D4, 1, 0)) -> 1
A5: 4 | B5: 3. Helicobacter ist die Hauptursache f. gastrointestinale Ulcera, aber nicht die einzige Ursache f. Übersäuerung des Magens, wie der Autor des Kommentars Aufstoßen - nein Danke!" behauptet. Eine H.p.-Eradikationstherapie bei ernährungsbedingten Beschwerden (zu viel Alkohol, Kaffee, fetthaltige Speisen) wäre unsinnig rausgeblasenes Geld. Darüber hinaus sind die Protonenpumpenhemmer bei der Eradikationstherapie die einzigen Medikamente, die die Magenschmerzen mindern (Ausnahme: bei der Quadrupeltherpie hat das Bismut einen positiven Effekt auf die Schleimproduktion und endogene Bikarbonatausscheidung). Im Übrigen: wer 3-4h nach Natrongabe aufstoßen muß, hat eindeutig zu viel genommen. 10:02, 15. Aug. 2008 (CEST) " | C5: Nicht feststellbar | D5: Nicht feststellbar | E5: =IF(C5="NICHT-ANALYSIERT", "NA", IF(C5=D5, 1, 0)) -> 1
A6: 5 | B6: Unabhängig davon: Was das CERN produzieren und speichern kann, wäre als Energiespeicher völlig witzlos. Hätte man sämtliche dort (innerhalb von Jahrzehnten) erzeugte Antimaterie gleichzeitig zur Verfügung, könnte man damit etwa einmal Kaffee kochen. -- 11:08, 26. Nov. 2013 (CET) | C6: Nicht feststellbar | D6: Nicht feststellbar | E6: =IF(C6="NICHT-ANALYSIERT", "NA", IF(C6=D6, 1, 0)) -> 1
A7: 6 | B7: Woher die Tasse kommt? Wolltest nicht Du in Deiner ersten Antwort etwa einmal Kaffee kochen."? Gruß ;) " | C7: Nicht feststellbar | D7: Nicht feststellbar | E7: =IF(C7="NICHT-ANALYSIERT", "NA", IF(C7=D7, 1, 0)) -> 1
A8: 7 | B8: Kaffee kochen - ja, aber Kaffee aus normaler Materie, mit der Energie der Annihilation der Antimaterie. Und wie gesagt, das auch nur wenn man Jahrzehnte der Produktion gleichzeitig zur Verfügung hätte, was nicht der Fall ist. Eine Tasse voller Antimaterie wäre eine völlig andere Größenordnung, und würde reichen um eine Großstadt zu zerstören. -- 00:09, 10. Dez. 2013 (CET) | C8: Nicht feststellbar | D8: Nicht feststellbar | E8: =IF(C8="NICHT-ANALYSIERT", "NA", IF(C8=D8, 1, 0)) -> 1
A9: 8 | B9: Fruchtfleisch, Samen, Rinde, Blätter und Sprößlinge des Affenbrotbaums sind vielseitig einsetzbar. Sie liefern Nahrung, Wasser, Kleidung, Material zum Dachdecken, Klebstoff, Medizin, Halsschmuck, Süßigkeiten, Schnüre, Seile, Netze, Matten, Hüte, Tabletts, Kisten, Körbe, Papier, Seife, Kaffee, Bier und Öl. | C9: Nicht feststellbar | D9: Nicht feststellbar | E9: =IF(C9="NICHT-ANALYSIERT", "NA", IF(C9=D9, 1, 0)) -> 1
A10: 9 | B10: Kaffee, Madeln, Karamel und Chilli | C10: Nicht feststellbar | D10: Nicht feststellbar | E10: =IF(C10="NICHT-ANALYSIERT", "NA", IF(C10=D10, 1, 0)) -> 1
A11: 10 | B11: Sonst spende ich stets den Freundlichen Gruß. In diesem Fall bin ich ob des frisch versenkten Arbeitsaufwandes schon extrem ungehalten. Wenn das nicht haarklein aufgeklärt wird, gibt´s einen Vandalismus-Rev, und vieleicht mal einen Antrag auf Benutzersperrung, weil ich nun ziemlich den Kaffee aufhabe. OK? Gruß 19:15, 5. Jun 2005 (CEST) | C11: Maskulinum oder Neutrum | D11: Maskulinum oder Neutrum | E11: =IF(C11="NICHT-ANALYSIERT", "NA", IF(C11=D11, 1, 0)) -> 1 | F11: Definiter Artikel, den
A12: 11 | B12: Wieso hat er es sich mit Heydrich verdorben"? Hat er ihm in den Kaffee gespuckt oder war seine Bügelfalte zu lasch? " | C12: Maskulinum oder Neutrum | D12: Maskulinum oder Neutrum | E12: =IF(C12="NICHT-ANALYSIERT", "NA", IF(C12=D12, 1, 0)) -> 1 | F12: Definiter Artikel, den
A13: 12 | B13: Nach einer Definition der Weltgesundheitsorganisation gilt jede Substanz als Droge, die in einem lebenden Organismus Funktionen zu verändern vermag. Dieser erweiterte Drogenbegriff erfaßt nicht nur Cannabisprodukte, Halluzinogene, Stimulantien, Schnüffelstoffe, Schlaf- und Beruhigungsmittel, Alkohol, Tabakerzeugnisse, Schmerzmittel Opiate und Kokain. Er bezieht sich auch auf Alltagsdrogen wie z.B. Kaffee und Tee und grenzt Drogen einerseits sowie Genuß- und "Lebens"mittel andererseits nicht mehr trennscharf voneinander ab"." | C13: Nicht feststellbar | D13: Nicht feststellbar | E13: =IF(C13="NICHT-ANALYSIERT", "NA", IF(C13=D13, 1, 0)) -> 1
A14: 13 | B14: Also etwas fragwürdig finde ich es schon, wenn ein Link angebracht wird, der auf eine Seite führt, die Kaffee vermarktet, selbst wenn &#x20ac; 1,00 an eine Kirchenschule geht. Rasselas - Ein Premiumkaffee des Prinzen Asfa-Wossen Asserate von Äthiopien Soziales Projekt des Prinzen Asfa-Wossen Asserate. Ich bin noch nicht lang genug bei Wiki um eigenständig in so einem Fall zu handeln, möchte es aber diskutieren. | C14: Nicht feststellbar | D14: Nicht feststellbar | E14: =IF(C14="NICHT-ANALYSIERT", "NA", IF(C14=D14, 1, 0)) -> 1
A15: 14 | B15: Interessant wird es aber, wenn man zu experimientieren beginnt. Also: Ich bin ein klassischer Übersäuerungskandidat: Zuviel Kaffee, gerne Zucker und schlechte Kohlenhydrate und auch Schweinefleisch. Seit einiger Zeit habe ich mit Müdigkeit zu kämpfen... | C15: Nicht feststellbar | D15: Nicht feststellbar | E15: =IF(C15="NICHT-ANALYSIERT", "NA", IF(C15=D15, 1, 0)) -> 1
A16: 15 | B16: Wieso empfiehlst Du aber Kaffee zu meiden? Ich konnte bislang keine größere empirische Studie finden, die einen Zusammenhang zwischen Kaffee und Alterung bzw. Lebenserwartung aufzeigt. Gibt es Substanzen im Kaffee, die das Altern beschleunigen, z.B. freie Radikale verursachen? | C16: Maskulinum oder Neutrum | D16: Maskulinum oder Neutrum | E16: =IF(C16="NICHT-ANALYSIERT", "NA", IF(C16=D16, 1, 0)) -> 1 | F16: Im Kaffee -> Präposition mit einem bestimmten Artikel
A17: 16 | B17: Sie müssen viel telfonieren um genug Kunden und Anwerber zu finden. Sich mit diesen treffen, Kaffee ausgeben und auch mobil sein (Benzin-, Fahrgeld). Sie werden sich vermutlich auch neu einkleiden müssen, stehts ordentlich auftreten - dazu genört auch Maniküre, Kosmetiksalon, Nagelstudio was innerhalb der Amway-Riege als ganz normal &amp;gt;verkauft&amp;lt; wird. Wieder lässt sich hier eine zweigleisigkeit erkennen. Denn ihr Verlangen nach Luxusartikel ist wie bei den meisten Menschen vermutlich gut ausgeprägt. Nun bei wem werden sie ihre neue Kosmetik kaufen? Die Luxusgüter - Parfum... | C17: Nicht feststellbar | D17: Nicht feststellbar | E17: =IF(C17="NICHT-ANALYSIERT", "NA", IF(C17=D17, 1, 0)) -> 1
A18: 17 | B18: Zum Frühstück gab es üblicherweise englisches Porridge, dazu Schinken und Eier, Wurst, Brot, Tee oder Kaffee. | C18: Nicht feststellbar | D18: Nicht feststellbar | E18: =IF(C18="NICHT-ANALYSIERT", "NA", IF(C18=D18, 1, 0)) -> 1
A19: 18 | B19: @tom:?? Ich weiß jetzt zwar nicht, warum Du dich angesprochen fühlst und dich so echauffierst, denn die Erläuterug steht oben (aktiv/passiv). Wie klare Begriffe im Alltag mitunter umgangssprachlich anders interpretiert/genutzt werden, ist was anderes (z.B. Igor's Kaffee, daher z.B. auch eine DIN). Und wie schon oben geschrieben, kommt es nicht darauf an, ob jemand da sitzt, sondern in welchem Kontext diese Arbeit ausgeführt wird... -- 10:41, 27. Jan 2006 (CET) | C19: Nicht feststellbar | D19: Nicht feststellbar | E19: =IF(C19="NICHT-ANALYSIERT", "NA", IF(C19=D19, 1, 0)) -> 1
A20: 19 | B20: sing* Morning has bro-ken, like the first mor-ho-horning, blackbird has spo-ken, like the first bird.... Die kleine vorgeschlagene Ergänzung würde darüberhinaus eine wunderschöne Symmetrie in die Einleitung bringen, wir hätten dann (bei meiner Bildschirmgröße und Auflösung) drei Absätze à je fünf Zeilen. Bei euch mag die Zeilenlänge variieren, hübsch anzusehen wäre es dennoch! Schönen Sonntag euch allen, ich gehe dann erstmal einen Schneesonnen-Spaziergang machen, wenn ich meinen Kaffee geschlürft habe...-- 11:12, 12. Feb 2006 (CET) | C20: Maskulinum oder Neutrum | D20: Maskulinum oder Neutrum | E20: =IF(C20="NICHT-ANALYSIERT", "NA", IF(C20=D20, 1, 0)) -> 1 | F20: meinen Kaffee -> possessives Pronomen, Akkusativ
A21: 20 | B21: Andererseits ist die Tun"-Form nicht ausschliesslich eine Zukunftsform. "Duesch (du) dä Esu choufä?" =&amp;gt; Tust du diesen Esel kaufen? "Sii duet tuschur parlierä bem Caffee tringke." =&amp;gt; Sie tut immer(tourjours) parlieren/sprechen beim Kaffee trinken. "Dueschmer schnäu dä Bryef schribe?" =&amp;gt; Tust (du) mir schnell diesen Brief schreiben. "Duesch das itze lo sy!" =&amp;gt; Tust (du) dies jetzt lassen sein! (Imperativ ;) ) (Es wäre aber auch "Losch das itze lo sy!" (Lässt (du) dies jetzt lassen sein) möglich. Oder noch kürzer: "Los lo sy!" (Las es lassen sein) " | C21: Maskulinum oder Neutrum | D21: Maskulinum oder Neutrum | E21: =IF(C21="NICHT-ANALYSIERT", "NA", IF(C21=D21, 1, 0)) -> 1 | F21: beim -> Präposition mit einem bestimmten Artikel
A22: 21 | B22: - Anita Kehrte aber ziemlich schnell nach Breslau zurück. - Die Familie wollte zusammen bleiben. - Einwanderung nach Amerika: schwierig w/ Codesystem. - Anita wollte nach Paris - die Rettung war greifbar nah. - Sie will wieder richtig arbeiten. - Juden hatten ein &#x201e;J&#x201c; auf ihren Karten. - Juden durften nur zu bestimmten Zeiten einkaufen gehen. - Juden mussten einen gelben Stern tragen. Nach dem Polenfeldzug begann die Deportationen ernsthaft - Anita hatte eine glückliche Kindheit, mit wenig Regeln: Sie durften niemals faul herumsitzen. Sonntagnachmittag mußten alle bei Tisch sein und Kaffee trinken. - Die Familie wollte immer noch auswandern. Aber es klappte nicht. - Man zog um zur Schwester der Mutter. Dort war es sehr eng - Anita schrieb am 15.01.1941: Sie geht wieder in die Schule als Schülerin und hat in 4 Wochen 2 Schuljahre nachgeholt. - Renate schrieb: sie arbeitet bei der Müllabfuhr, ist jetzt krank. Sie musste Zahnpastatuben und Metalle aus toten Ratten aussortieren. - Anita gibt Lateinunterricht - Sie ist überall gut in der Schule - Die Schule wurde geschlossen -&amp;gt; man traf sich in den Privatwohnungen der Lehrer, um weiter zu lernen - Anita gehörte zu den 10 Besten, die an eine andere Schule verschickt wurden - Renate mußte in einer Papierfabrik arbeiten. - In dieser Fabrik arbeitete Anita später auch. - 09.04.1942 Eltern werden deportiert (die Kinder waren zu der Zeit in der Fabrik) - Die Kinder hätten auch mitkommen können. Doch der Vater wollte, dass sie zum Schutz allein zuhause blieben. - Vater schreibt Briefe und hofft, wieder zurückzukommen, Mutter sei fix und fertig, - 8. auf 9. 04.01942: Vater ruft an und wusste, dass er nicht mehr zurückkommt. Er erklärt Anita, wie man Miete und Strom zahlt. Sie durfte seine Unterschrift fälschen. Ihr Vater verließ sich auf sie. - Letzte Worte des Vaters an Anita: &#x201e;Anita, pass auf deinen Gang auf&#x201c; - Graf Kinigel wollte den Eltern helfen. Er verlangte von der Gestapo, dass der Vater freigelassen werden sollte, da man ihn brauchte. Wenn der Name noch nicht registriert sei, würde man ihn freilassen. - Anita und ihre Schwester waren auf sich allein gestellt - Bei der Großmutter, die 82 Jahre war (schwierig) und mit dem alten Ehepaar, welches schon lange Zeit, bevor sie eingezogen waren, Untermieter ihrer Tante war. - Doch ihr Onkel und ihre Tante sind schon deportiert worden - Das hieß aber nicht, daß endlich mehr Platz durch freie Zimmer entstand. Die verlassenen Räume wurden nämlich versiegelt - Die Großmutter weigert sich, das Passierte wahrzuhaben. - Anita und Renate arbeiten wieder in der Fabrik, da sie sich um die Lebensmittel kümmern mussten. - Dies war aber schwierig, da Juden nur zu bestimmten Zeiten und begrenzt einkaufen durften - Anita und Renate stahlen gebrauchte Reisemarken, die weder mit Datum, noch mit dem Namen der Besitzer, noch mit &#x201e;J&#x201c; für Jude gekennzeichnet waren. - Somit konnten sie im jeden Geschäft einkaufen - Renate ging einkaufen, da sie weniger jüdisch aussah als Anita. - Die einzigen, die sie noch haben sind Verwandte in der Schweiz (Tante Vally und Onkel Siegfried). - Anita und Renate geht es gesundheitlich nicht sehr gut da sie viel arbeiten müssen. - Die Großmutter wird deportiert, verstand aber nicht, was mit ihr passierte. Bis zum letzten Moment bewarte sie Stolz und Würde. - Nach ihrer Deportation wurde noch ein Zimmer versiegelt - Anita und Renate sollen ins Waisenhaus. Sie wollen nicht. Aber ihnen bleibt keine andere Wahl. - Das alte Ehepaar ist nämlich auch fort gegangen. - Einen verzweifelten Brief, den Anita an ihre Tante und ihren Onkel geschrieben hat, schickt die Tante an ihren Sohn Harry weiter, der Beziehungen mit Menschen an der Schweizer Grenze hatte. - Dieser hatte einen Plan, der genial aber auch vollkommen unrealistisch war: - Er wollte Anita und Renate über die Grenze in die Schweiz schmuggeln. - Anita und Renate brauchten einen Plan, ohne daß jemand es merkte, aus dem Weisenhaus zu kommen, und ohne daß andere Menschen hineingezogen wurden. - Lösung : Sie gingen angeblich zur Arbeit. - In der Papierfabrik gab es getrennte Toiletten für Juden, Polen und Deutsche. - In der Judentoilette war ein Loch in der Wand. Auf der anderen Seite waren französische Kriegsgefangene. - Sie konnten dort Botschaften austauschen und sich unterhalten. - Renate und Anita fälschten Urkunden und stellten Urlaubsscheine für französische Zivilarbeiter aus. - Dies maachten sie mit der Schreibmaschine ihres Vaters. Gestempelt wurden diese Dokumente von Leuten des Widerstandes.. - Anita und Renate machten so auch Papiere für sich. Anita hieß Madeleine Demontaigne. - Ihre Freunde Ruth und Werner Krumme begleiteten sie. Doch alle vier wurden von der Gestapo verhaftet. - Werner war Arier. Er überlebte als Häftling. Doch Ruth war Jüdin. Sie wurde vergast. - Renate und Anita hatten die Chance, zu flüchten. Sie kamen zum Bahnhof in Paris. Doch in dem Augenblick, als sie einsteigen wollten, wurden sie von der Gestapo verhaftet. - Renate hatte schon einmal Zyankali von Konrad Latte bekommen. Da sie aber nicht geflohen sind, hatte er es wieder. - Doch für Paris gab er es ihr wieder. Aber es war Puderzucker, was sie nicht wußten. - Renate und Anita wollten sich auf dem Weg von der Polizei zur Gestapo damit umbringen - Anita und Renate taten so, als ob sie Französinnen wären. - Urteil: Renate 3 ½ Jahre Zuchthaus - Anita 18 Monate Gefängnis - Es waren immer 4 Personen in einer Zelle - Die schlimmste Erinnerung war das Schlüsseldrehen im Schloss. - Auftakt zur Arbeit : Zinnsoldaten anmalen - Eine Kollegin im Gefängnis war total gegen Juden und beschimpfte sie immer : &#x201e;Du kommst in die Gaskammer.&#x201c; - Anita musste für die Soldaten an der Front Strümpfe stricken. Sie war verzweifelt, weil sie das nicht konnte. Die Frau, die für die Verteilung der Arbeit zuständig war, hatte Mitleid mit ihr und lies sie Netze machen. - Anita konnte so ihre Zeit vertreiben. Doch sie hatte mehr Eifer als alle Anderen und hatte am Ende doppelt so viele Netze wie die Anderen. Ihr wurde gedroht. Deshalb trennte sie abends alles noch einmal auf und machte die Netze noch einmal. - Anita musste zum Zahnarzt. Dort sagte ihr eine Frau, die entsetzlichen Gespräche über Auschwitz seien wahr. - Der Aufseher bestellte Anita ins Büro. Dort musste sie unterschreiben, dass sie nach Auschwitz abtransportiert wird. - Im KZ musste sie sich ausziehen. Ihr Kopf wurde rasiert, und die Nummer 69388 wurde auf ihren linken Arm tätowiert.- Anita erzählte dem Mädchen, das ihr die Haare abschnitt, dass sie Cello spielt. Daraufhin hörte sie von ihr: &#x201e;Phantastisch, Du wirst gerettet werden.&#x201c; - Anita hatte keine Ahnung, was gemeint war. Aber sie tat, was ihr gesagt wurde, und stellte sich abseits von allen Anderen. Splitternackt, mit kahlem Kopf und einer Zahnbürste in der Hand wartete sie. - Dann kam Alma Rosé (eine jüdische Geigerin). Sie war begeistert - Für Anita war das alles wie ein Traum. - Anita musste erst einmal in Quarantäne - Das Appellstehen war sehr schlimm. Es war verboten, sich zu bewegen. Das Zählen dauerte manchmal Stunden. Für Leute mit Durchfall war es besonders schlimm: Man stand da mit fürchterliche Krämpfen, während die Scheiße einem an den Beinen herunterlief &#x201e;Keiner der nicht dort war, kann sich vorstellen, wie groß unser Elend war.&#x201c; - Der SS-Offizier Hössler rief eines Tages nach der Cellistin - Er brachte sie zum Orchesterblock. Dort spielte sie den &#x201e;langsamen Satz&#x201c; aus dem Boccherini Konzert vor. - Anita wurde Mitglied des Lager-Orchesters. - Auch Leute, die keine Instrumente spielten konnten als Notenschreiber aufgenommen werden - Aufgabe: Marschmusik spielen. - Anita bekam Flechttyphus. Sie dachte, nun würde sie sterben. Aber sie überlebte und konnte weiter Cello spielen. - Es wurden Konzerte im Lager gegeben. - Anita traf plötzlich Renate wieder. - Erkennungszeichen: Die alten Schuhe von Anita, die sie der Frau gegeben hatte, die ihr die Haare abrasiert hatte. - Sie erzählten sich gegenseitig von der Zeit, in der sie getrennt gewesen waren. - Renate bekam auch Typhus, wurde aber nicht so schnell wieder gesund wie Anita. Aber sie überlebte. - Anita sorgte dafür, dass Renate als &#x201e;Läuferin&#x201c; eingesetzt wurde - -&amp;gt; Renate bekam bessere Rationen und war auf dem Weg der Besserung. - Als Läuferin wartete man darauf, Nachrichten zu übergeben.Man durfte im ganzen Lager frei herumlaufen. - Manche wurden frei gelassen. Diese hatten 1 Stunde Zeit ihre Sachen zu packen, wenn davon noch etwas übrig geblieben war. - Es entstanden Freundschaften. Alle hielten zusammen. - Im Mai 1944 kamen die Juden aus Ungarn. 24000 Ungaren wurden an einem Tag ermordet. - Keiner wusste mehr, was außerhalb des Lagers geschah. - Ende Oktober 1944 mussten sich Arier auf einer und Juden auf der anderen Seite aufstellen. - Alle dachten, es ginge zur Gaskammer. Sie stiegen in Transporter und fuhren irgendwo hin. - Sie kamen nach Bergen-Belsen. - Dies war ein kleines KZ mit &#x201e;nur&#x201c; 1000 lagerinsassen. Nun kamen 3000 hinzu. Sie hatten keinen Platz. - Die Neuankömmlinge wurden in einem Zelt untergebracht. - Am nächsten Morgen kamen alle in den Lagerraum und später in eine Baracke. - Viele starben, da sie keine Kraft mehr hatten. - Arbeit: Cellophan flechten. - Jeder erlebte Tag war wie ein Wunder. - Die Häftlinge bekamen weder Essen noch Trinken. - Alles seltsam: Immer weniger SS-Leute zu sehen - Plötzlich kamen englische Panzer: Hoffnung! - Ein Engländer sagte: &#x201e;Hier ist die britische Armee. Bitte bleibt ruhig. Wir sind gekommen, um Euch zu befreien. Verlasst nicht das Lager. Habt keine Angst. Ihr seid frei.&#x201c; - Zum Jubeln hatten sie keine Kraft mehr. - Befreiung:1 5.04.1945 um 4 Uhr nachmittags. - Die Panzer kamen drei Tage nach dem Waffenstillstand. - Durch das Fernsehen stellten sie Kontakte zu ihren Bekannten her. Sie schrieben an Marianne. - Sie bekamen wieder Essen und Trinken. - Familie und Verwandte versuchten, eine Einreisegenehmigung zu bekomme. Doch es war aussichtslos. - Sie bekamen Gelegenheit, nach Brüssel zu fahren (Dez. 1945). - (mit gefälschten Papieren. Der Versuch glückte!!) - Sie kamen bei einer Freundin aus dem KZ unter. - Sie versuchten von da aus, Papiere für England zu bekommen. - Anita konnte auch wieder Cello spielen. - 18. März 1946 Abfahrt nach England! - Der Kapitän war stolz zwei, Ex-Belsen Gefangene an Bord zu haben. - Anita wohnt bis heute in England, doch traf sie nur zweimal in ihrem Leben ihre Schwester Marianne wieder. - Sie wollte nie mehr einen Fuß auf deutschen Boden setzen!! | C22: Nicht feststellbar | D22: Nicht feststellbar | E22: =IF(C22="NICHT-ANALYSIERT", "NA", IF(C22=D22, 1, 0)) -> 1 | F22: "sein und" wird als possessives Pronomen interpretiert
A23: 22 | B23: Warum? Die eindeutige Zuordnung zur heutigen Türkei ist nicht möglich, da es offenbar im gesamten Osmanische Reich verbreitet war. Auch ist die Unterscheidung in türkischen" und "deutschen" Joghurt sehr willkürlich und wenn man so will "Deutschlandlastig". Ich weiß nicht sehr viel über Joghurtbakterien, aber es scheint hier eher um die Verwendung von Lactobacillus delbrueckii subspecies bulgaricus und Lactobacillus acidophilus zu gehen, welche zwar vieleicht national unterschiedlich stark Verwendung finden, aber keinem Kulturkreis eindeutig zuzuordnen sind. Das mit der ländlichen Türkei klingt zwar romantisch, aber kann man genauso gut mit Tee oder Kaffee ersetzen. 21:30, 5. Jun. 2008 (CEST) " | C23: Nicht feststellbar | D23: Nicht feststellbar | E23: =IF(C23="NICHT-ANALYSIERT", "NA", IF(C23=D23, 1, 0)) -> 1
A24: 23 | B24: Kaffee | C24: Nicht feststellbar | D24: Nicht feststellbar | E24: =IF(C24="NICHT-ANALYSIERT", "NA", IF(C24=D24, 1, 0)) -> 1
A25: 24 | B25: Kaffee ein Antivitamin? Auf der Seite http://www.uni-bayreuth.de/departments/didaktikchemie/umat/kaffee1/1_kaffee1.htm wird das beispielsweise widerlegt weiss jemand genaueres? Die Information auf dieser Wiki Seite sind recht dürftig | C25: Nicht feststellbar | D25: Nicht feststellbar | E25: =IF(C25="NICHT-ANALYSIERT", "NA", IF(C25=D25, 1, 0)) -> 1
A26: 25 | B26: Ich habe versucht, die Beispiele aus dem sehr guten Artikel der österreichischen Apothekerzeitung nach Wirkmechanismen zu ordnen. Beim Kaffee ist die Antivitaminwirkung eine Frage der Dosis. Normale Ernährung und normaler Kaffeegenuß führen nicht zu einer Vitaminmagnelwirkung. 12:31, 20. Apr. 2007 (CEST) | C26: Maskulinum oder Neutrum | D26: Maskulinum oder Neutrum | E26: =IF(C26="NICHT-ANALYSIERT", "NA", IF(C26=D26, 1, 0)) -> 1 | F26: beim -> Präposition mit einem bestimmten Artikel
A27: 26 | B27: Okay. Ich verstehe Deinen Punkt jetzt. Danke! Zu den häufigsten Lebensmittelquellen zählt er freilich nicht, da die wenigsten Menschen reglemäßig Granatäpfel konsumieren - im Gegensatz zu Kaffee zum Beispiel. Dennoch ist er eines der wirksamsten Antioxidantien. Du hast ihn ja schon oben in die Tabelle aufgenommen. Vielleicht könnte man ihn im Text trotzdem noch einmal erwähnen... Viele Grüße, -- 09:58, 14. Jul. 2011 (CEST) | C27: Nicht feststellbar | D27: Nicht feststellbar | E27: =IF(C27="NICHT-ANALYSIERT", "NA", IF(C27=D27, 1, 0)) -> 1
A28: 27 | B28: @Plenz: Geschwister müssen nicht die gleichen Vorlieben haben, da sich die Lernumwelt, die entscheidend für den Erwerb von Geschmackspräferenzen zu sein scheint, unterschiedlich sein kann. Andererseits wäre es auch möglich, das die Geschwister unterschiedliche Modelle wählen (Vater: Kaffee, Mutter: Tee, nur als Beispiel) oder sich die Eltern unterschiedlich ihren Kindern gegenüber verhalten. Möglich wäre, das ein Junge dafür belohnt wird, das er hochkalorische Sachen isst (damit er groß und stark wird ;-) ), ein Mädchen eventuell dafür nicht (hochkalorische Sachen können dick machen). Das würde dazu führen, das sich, aufgrund assoziativer Lernprozesse (Konditionieren) unterschiedliche Präferenzen bilden. Grüße, 19:03, 13. Apr. 2007 (CEST) | C28: Nicht feststellbar | D28: Nicht feststellbar | E28: =IF(C28="NICHT-ANALYSIERT", "NA", IF(C28=D28, 1, 0)) -> 1
A29: 28 | B29: Der Begriff Pott" ist inzwischen ähnlich dem "Tschüß" schon nicht mehr so auf Norddeutschland beschränkt wie vielleicht vor 20 Jahren. Hier in Berlin kann man neben der "Latte" inzwischen an vielen Stellen, besonders an populären Orten, normalen Kaffee im "Pott" bestellen. Dieser Sprachgebrauch ist nach meinem Eindruck Deutschlandweit im Vormarsch. " | C29: Maskulinum oder Neutrum | D29: Maskulinum oder Neutrum | E29: =IF(C29="NICHT-ANALYSIERT", "NA", IF(C29=D29, 1, 0)) -> 1 | F29: Adjektivflexion, -en
A30: 29 | B30: Liebe Barb, offenbar habe ich mit meinem Versuch, persönliche Attacken zu unterbinden, dir nur noch weiter Zucker in den Kaffee getan. Ich sehe, dass du aus der Sachdebatte gerne eine Personendebatte machen möchtest: du disqualifizierst dich selbst", "oberflächlich, "arrogant" und so weiter. Fehlen dir auf der Sachebene dermaßen die Argumente? Das ist ein Gesprächsverhalten, das ich leider vor allem von Feministinnen kenne, auch wenn sie von sich selbst behaupten, aber sowas von neutral zu sein. Selbstverständlich ist es weder oberflächlich noch arrogant, nachweisbar unsinnige Behauptungen als solche zurückzuweisen. Was also solche Herabsetzungen deinerseits angeht, halte ich es doch lieber mit dem alten Spruch, dass wenn jemand mit dem Finger auf andere zeigt, vier Finger auf ihn selbst zurückweisen. Ansonsten nehme ich mit Interesse zur Kenntnis, dass die von mir behandelten Themen (Ungleichbehandlung von Männern in Jusiz, Schule und Gesundheitswesen, männliche Opfer häuslicher Gewalt, sexueller Missbrauch durch Frauen etc.pp.) offenbar bei einigen Frauen dermaßen unerwünscht sind, dass sie solche Reaktionen der persönlichen Diskreditierung auslösen. - Arne " | C30: Maskulinum oder Neutrum | D30: Maskulinum oder Neutrum | E30: =IF(C30="NICHT-ANALYSIERT", "NA", IF(C30=D30, 1, 0)) -> 1 | F30: In den -> definiter Artikel
A31: 30 | B31: Lieber Arne, ich trinke meinen Kaffee gern schwarz. Mit der persönlichen Attacke hast du angefangen, in dem du einer anderen Diskussionsteilnehmerin ihre persönliche Qualifikation abgesprochen hast. Und machst weiter mit persönlichen Unterstellungen. Da hast du gut von den Feministinnen gelernt. In meinem zweiten Posting gehe ich auf zwei falsche Annahmen von dir ein, von denen du aber anscheinend so fest überzeugt bist, dass du eh nicht davon abzubringen bist. Es gibt den schönen Spruch: Jeder, der nicht meine Dfreund ist, ist mein Feind." bei dir wohl eher: "Jeder, der nicht meine Freund ist, ist eine Feministin." " | C31: Maskulinum oder Neutrum | D31: Maskulinum oder Neutrum | E31: =IF(C31="NICHT-ANALYSIERT", "NA", IF(C31=D31, 1, 0)) -> 1 | F31: meinen Kaffee -> possessives Pronomen, Akkusativ
A32: 31 | B32: Was hat vegane Ernährung mit Adipositas zu tun? Zuckerhaltige Limonaden wie Cola/Fanta, Pommes, Nudeln, Pizza, Kuchen, Speiseeis, Zuckerwaren, Tabak, Alkohol, Kaffee - alles vegan oder vegan möglich. Die hier genannten Ursachen zeigen dazu noch, wie vielfältig die Gründe sind, welche nicht durch eine Methode allein zu beheben sind. 15:38, 23. Mär. 2016 (CET)timestamp | C32: Nicht feststellbar | D32: Nicht feststellbar | E32: =IF(C32="NICHT-ANALYSIERT", "NA", IF(C32=D32, 1, 0)) -> 1
A33: 32 | B33: Verzweifelte Klimmzüge! LITERATUR zu: Anti-Islamismus muß her. Der Rest ist kalter Kaffee und POV auch in der Disku.-- 23:31, 25. Jul. 2007 (CEST) | C33: Maskulinum oder Neutrum | D33: Maskulinum oder Neutrum | E33: =IF(C33="NICHT-ANALYSIERT", "NA", IF(C33=D33, 1, 0)) -> 1 | F33: Adjektivflexion, -er
A34: 33 | B34: Schönen Tag mit Kaffee Hag. -- 21:36, 29. Mär. 2007 (CEST)timestamp | C34: Nicht feststellbar | D34: Nicht feststellbar | E34: =IF(C34="NICHT-ANALYSIERT", "NA", IF(C34=D34, 1, 0)) -> 1
A35: 34 | B35: denn er impliziert, daß es 1995 eine DDR gab, und das trifft nicht zu. 1995 war die DDR bereits Vergangenheit. Daher &#x201e;Ehemalige DDR&#x201c;. Oder würdest Du z. B. schreiben, daß &#x201e;gestern der Bundeskanzler Gerhard Schröder einen Kaffee trank&#x201c;? Gruß, 15:07, 29. Okt. 2007 (CET) | C35: Maskulinum oder Neutrum | D35: Maskulinum oder Neutrum | E35: =IF(C35="NICHT-ANALYSIERT", "NA", IF(C35=D35, 1, 0)) -> 1 | F35: Adjektivflexion, -en
A36: 35 | B36: In dem Wikipedia-Artikel wird behauptet, sie habe angeblich Psychologie studiert. Diese Behauptung erscheint jedoch zweifelhaft. Denn sie hat offenbar keine allgemeine Hochschulreife (kein Abitur). Über eine Höhere Handelsschule hätte sie zwar immerhin ein Fachabitur und somit den Zugang zu einem Fachhochschulstudium erreichen können. Aber erstens bieten Fachhochschulen kein Psychologie-Studium an (Psychologie ist ein universitärer Studiengang und Numerus-Clausus-Fach), und zweitens hat sie ja wohl auch keine höhere Handelsschule besucht, sondern anscheinend bloß eine einfache Handelsschule (wobei selbst da nicht feststeht, ob sie wenigstens dort denn einen erfolgreichen Abschluss erreicht hat). Anscheinend hat sie (ähnlich wie Joschka Fischer) ohne Abitur und ohne Fachhochschulreife bloß gelegentlich in Studentenwohnheimen oder studentischen Wohngemeinschaften und Uni-Mensen sowie auf Uni-Partys, und ab und zu auch in universitären Hörsäälen oder Bibliotheken herumgehangen, und in Uni-Cafeterien mit Studenten und Professoren Kaffee getrunken und mit denen ein bischen rumgelabert, aber sie hat wohl nie eine wirkliche Hochschulausbildung durchlaufen oder gar erfolgreich abgeschlossen, und schon gar nicht in der Fachrichtung Psychologie (das Numerus-Clausus-Studium der Psychologie erfolgreich zu meistern und erfolgreich abzuschließen ist zumindest an deutschen Universitäten auch gar nicht so einfach). Sie dürfte wohl eher ein Autodidakt" sein. Und Autodidakten neigen im Allgemeinen dazu, nicht streng wissenschaftlich zu arbeiten, sondern vielmehr lediglich zu den Erkenntnissen zu kommen, zu denen sie vom Ergebnis her kommen wollen. Autodidakten lernen selten eine selbstkritische unparteiische und unvoreingenommene Herangehensweise an ein Thema, sondern neigen häufig zu Voreingenommenheit und Parteilichkeit. -- 23:31, 13. Feb. 2012 (CET)timestamp " | C36: Nicht feststellbar | D36: Nicht feststellbar | E36: =IF(C36="NICHT-ANALYSIERT", "NA", IF(C36=D36, 1, 0)) -> 1
A37: 36 | B37: Zitat aus Brasilien:Mit großen, gut entwickelten Landwirtschafts-, Bergbau-, Produktions-, und Dienstleistungssektoren auf der einen Seite und einem großen Vorrat an Arbeitskräften auf der anderen ist die brasilianische Wirtschaft die kräftigste Südamerikas und gewinnt auf dem Weltmarkt an Bedeutung. Die wichtigsten Exportprodukte sind Kaffee, Kakao, tropische Früchte, Sojabohnen und Eisenerz. 40 % der brasilianischen Agrarausfuhren gehen in die EU, 17 % in die USA. Zu den größten Herausforderungen für die brasilianische Wirtschaft zählen nach wie vor die Inflation und die Kluft zwischen einer wohlhabenden, gut ausgebildeten Bevölkerungsminderheit und der schlecht ausgebildeten Mehrheit, die größtenteils am Rande des Existenzminimums lebt. Es gibt eine große Bewegung von Landlosen, die Movimento dos sem terra, die für eine Landreform kämpfen. | C37: Nicht feststellbar | D37: Nicht feststellbar | E37: =IF(C37="NICHT-ANALYSIERT", "NA", IF(C37=D37, 1, 0)) -> 1
A38: 37 | B38: Ich würde als Lösung vorschlagen, dass Dir mal einen ruhigen Nachmittag machst, vielleicht etwas Kaffee mit vor den PC nimmst und den Artikel einmal komplett von oben bis unten abschreibst. Vorher ein paar Mal durchlesen (nicht zu oft, sonst bleiben die Sätze so hängen) und dabei darauf achtest, wo Du aus der Kurve fliegst. Alternativ kann ich Dir anbieten, dass für Dich zu machen. Vielleicht mögen außer mir ja auch noch andere Menschen Texte, die nicht nur informativ sind, sondern sich auch angenehm vom Anfang bis zum Ende lesen lassen. Ein Kriterium bei den Auszeichnungen ist es jedenfalls :-) In der Hoffnung, Dir zumindest irgendwie geholfen zu haben, 21:05, 22. Jul. 2010 (CEST) | C38: Nicht feststellbar | D38: Nicht feststellbar | E38: =IF(C38="NICHT-ANALYSIERT", "NA", IF(C38=D38, 1, 0)) -> 1
A39: 38 | B39: Also bitte, Kaffee / Tee / Kakao für lau kompensiert ja wohl kein geringes Gehalt. Die Aktion mit den Stückchen ist gut, ja, allerdings kriegt man das auch nur zur Frühschicht ab (in denen der vorbildliche Student sich in einer Vorlesung aufhält..). Die Zuschüsse / Rabatte zu diversen Mittagsessen hielten sich ebenfalls stark in Grenzen. Mein gesicherter" Mitarbeiterparkplatz unterschied sich nicht nennenswert von dem Zustand eines Feldweges. Ich möchte da nun nicht weiter darauf eingehen, aber in meiner Zeit habe ich festgestellt, dass ein Großteil der Angestellten "entsprechend ihrem Lohn motiviert" arbeiten. Mit einem besseren Gehalt könnte man automatisch mehr von den Leuten erwarten (schon bei der Einstellung). Aber sie beschäftigen lieber einen Haufen unzuverlässiger Leute, die wo es nur geht bei der verrichteten Arbeit und der Arbeitszeit beschei**en. -- 22:46, 19. Sep. 2010 (CEST) " | C39: Nicht feststellbar | D39: Nicht feststellbar | E39: =IF(C39="NICHT-ANALYSIERT", "NA", IF(C39=D39, 1, 0)) -> 1
A40: 39 | B40: Offenbar hatte ich zuwenig Kaffee intus. Danke. -- 08:27, 20. Sep. 2007 (CEST) | C40: Nicht feststellbar | D40: Nicht feststellbar | E40: =IF(C40="NICHT-ANALYSIERT", "NA", IF(C40=D40, 1, 0)) -> 1
...

Sheet Statistik
B2: Ergebnis | C2: Genuszuweisung (manuell) | E2: Genuszuweisung (Algorithmus) | G2: Differenz
C3: n | D3: % | E3: n | F3: % | G3: n | H3: %
B4: Nicht feststellbar | C4: =COUNTIF('Manuelle Überprüfung von 150'!C2:C943, B4) -> 82 | D4: =C4/C$7 -> 0.54666667 | E4: =COUNTIF('Manuelle Überprüfung von 150'!D2:D943, B4) -> 83 | F4: =E4/E$7 -> 0.55333333 | G4: =C4-E4 -> -1 | H4: =F4-D4 -> 0.0066666667
B5: Maskulinum oder Neutrum | C5: =COUNTIF('Manuelle Überprüfung von 150'!C2:C944, B5) -> 68 | D5: =C5/C$7 -> 0.45333333 | E5: =COUNTIF('Manuelle Überprüfung von 150'!D2:D944, B5) -> 65 | F5: =E5/E$7 -> 0.43333333 | G5: =C5-E5 -> 3 | H5: =F5-D5 -> -0.02
B6: Femininum | C6: =COUNTIF('Manuelle Überprüfung von 150'!C2:C945, B6) -> 0 | D6: =C6/C$7 -> 0 | E6: =COUNTIF('Manuelle Überprüfung von 150'!D2:D945, B6) -> 2 | F6: =E6/E$7 -> 0.013333333 | G6: =C6-E6 -> -2 | H6: =F6-D6 -> 0.013333333
B7: Summe | C7: =SUM(C4:C6) -> 150 | D7: =SUM(D4:D6) -> 1 | E7: =SUM(E4:E6) -> 150 | F7: =SUM(F4:F6) -> 1 | G7: =SUM(G4:G6) -> 0 | H7: =SUM(H4:H6) -> 8.1532003e-17
C9: n | D9: %
B10: Absolute Differenz | C10: =ABS(G4)+ABS(G5)+ABS(G6) -> 6 | D10: =C10/C7 -> 0.04
B12: Korrektheit | C12: n | D12: %
B13: Inkorrekte Ergebnisse | C13: =COUNTIF('Manuelle Überprüfung von 150'!E1:E944, 0) -> 7 | D13: =C13/(C13+C14) -> 0.046666667
B14: Korrekte Ergebnisse | C14: =COUNTIF('Manuelle Überprüfung von 150'!E1:E944, 1) -> 143 | D14: =C14/(C13+C14) -> 0.95333333
